Workbook
Name DashboardYearOptions: OFFSET('Reference Data'!$G$2,0,0,COUNTA('Reference Data'!$G:$G)-1,1)

Sheet Dashboard
B3: SALES | G3: Revenue | K3: Target | O3: Delta (Revenue vs Target) | S3: Sales Records
G4: ='Helper Tables'!$D$24 -> 98992100 | K4: ='Helper Tables'!$D$25 -> 96972000 | O4: ='Helper Tables'!$D$26 -> 2020100 | S4: ='Helper Tables'!$D$27 -> 3000
B6: =$B$11&" | "&$B$19&" | "&$B$15 -> 2026 | All | All
B10: Year
B11: 2026
B14: Region
B15: All
B18: Month | H18: ='Helper Tables'!$D$28 -> 1.0208318
B19: All
H21: of target
B23: Choose a year, region and month above. KPIs, achievement, salesperson, product and daily views follow your filters. The region chart compares all four regions for the chosen year and month. Monthly revenue and delta show all months for the selected year and region. When Month = All, the daily chart shows the latest month with data.

Sheet Daily Summary
A1: sale_date | B1: orders | C1: units | D1: revenue
A2: 46035 | B2: 15 | C2: 50 | D2: 612100
A3: 46120 | B3: 12 | C3: 39 | D3: 549400
A4: 46249 | B4: 15 | C4: 41 | D4: 932800
A5: 46277 | B5: 10 | C5: 35 | D5: 553800
A6: 46051 | B6: 12 | C6: 47 | D6: 423700
A7: 46180 | B7: 11 | C7: 31 | D7: 451500
A8: 46063 | B8: 13 | C8: 42 | D8: 266200
A9: 46324 | B9: 6 | C9: 18 | D9: 100200
A10: 46056 | B10: 5 | C10: 13 | D10: 103200
A11: 46060 | B11: 6 | C11: 18 | D11: 297600
A12: 46133 | B12: 13 | C12: 39 | D12: 280900
A13: 46147 | B13: 7 | C13: 19 | D13: 210000
... A304: 46248 | B304: 8 | C304: 18 | D304: 132800

Sheet Monthly Performance
A3: Row Labels | B3: Revenue | C3: Target | D3: Delta | E3: Achievement
A4: 01 Jan | B4: 11000700 | C4: 10536000 | D4: 464700 | E4: 1.0441059
A5: 02 Feb | B5: 9660300 | C5: 9005000 | D5: 655300 | E5: 1.0727707
A6: 03 Mar | B6: 9313200 | C6: 8673000 | D6: 640200 | E6: 1.0738153
A7: 04 Apr | B7: 8479500 | C7: 8307000 | D7: 172500 | E7: 1.0207656
A8: 05 May | B8: 9746200 | C8: 9652000 | D8: 94200 | E8: 1.0097596
A9: 06 Jun | B9: 10017300 | C9: 10158000 | D9: -140700 | E9: 0.98614885
A10: 07 Jul | B10: 8746500 | C10: 8373000 | D10: 373500 | E10: 1.0446077
A11: 08 Aug | B11: 11131900 | C11: 11163000 | D11: -31100 | E11: 0.99721401
A12: 09 Sep | B12: 11360800 | C12: 11051000 | D12: 309800 | E12: 1.0280337
A13: 10 Oct | B13: 9535700 | C13: 10054000 | D13: -518300 | E13: 0.94844838
A14: Grand Total | B14: 98992100 | C14: 96972000 | D14: 2020100 | E14: 1.0208318

Sheet Monthly Trend
A1: sale_year | B1: sale_month | C1: month_name | D1: revenue | E1: orders
A2: 2026 | B2: 1 | C2: Jan | D2: 11000700 | E2: 327
A3: 2026 | B3: 2 | C3: Feb | D3: 9660300 | E3: 283
A4: 2026 | B4: 3 | C4: Mar | D4: 9313200 | E4: 300
A5: 2026 | B5: 4 | C5: Apr | D5: 8479500 | E5: 281
A6: 2026 | B6: 5 | C6: May | D6: 9746200 | E6: 280
A7: 2026 | B7: 6 | C7: Jun | D7: 10017300 | E7: 306
A8: 2026 | B8: 7 | C8: Jul | D8: 8746500 | E8: 325
A9: 2026 | B9: 8 | C9: Aug | D9: 11131900 | E9: 307
A10: 2026 | B10: 9 | C10: Sep | D10: 11360800 | E10: 301
A11: 2026 | B11: 10 | C11: Oct | D11: 9535700 | E11: 290

Sheet Reference Data
A1: month_no | B1: month_label | D1: salesperson | E1: region | G1: year
A2: 1 | B2: =TEXT(DATE(2026,A2,1),"MM MMM") -> 01 Jan | D2: Salesperson 02 | E2: South | G2: 2026
A3: 2 | B3: =TEXT(DATE(2026,A3,1),"MM MMM") -> 02 Feb | D3: Salesperson 06 | E3: North
A4: 3 | B4: =TEXT(DATE(2026,A4,1),"MM MMM") -> 03 Mar | D4: Salesperson 04 | E4: South
A5: 4 | B5: =TEXT(DATE(2026,A5,1),"MM MMM") -> 04 Apr | D5: Salesperson 05 | E5: West
A6: 5 | B6: =TEXT(DATE(2026,A6,1),"MM MMM") -> 05 May | D6: Salesperson 07 | E6: North
A7: 6 | B7: =TEXT(DATE(2026,A7,1),"MM MMM") -> 06 Jun | D7: Salesperson 03 | E7: East
A8: 7 | B8: =TEXT(DATE(2026,A8,1),"MM MMM") -> 07 Jul | D8: Salesperson 08 | E8: West
A9: 8 | B9: =TEXT(DATE(2026,A9,1),"MM MMM") -> 08 Aug | D9: Salesperson 01 | E9: East
A10: 9 | B10: =TEXT(DATE(2026,A10,1),"MM MMM") -> 09 Sep
A11: 10 | B11: =TEXT(DATE(2026,A11,1),"MM MMM") -> 10 Oct
A12: 11 | B12: =TEXT(DATE(2026,A12,1),"MM MMM") -> 11 Nov
A13: 12 | B13: =TEXT(DATE(2026,A13,1),"MM MMM") -> 12 Dec

Sheet Product Summary
A1: product_name | B1: category | C1: units_sold | D1: revenue
A2: Laptop | B2: Computers | C2: 714 | D2: 39270000
A3: Smartphone | B3: Mobiles | C3: 849 | D3: 18678000
A4: Tablet | B4: Mobiles | C4: 693 | D4: 12474000
A5: Monitor | B5: Computers | C5: 712 | D5: 8544000
A6: Printer | B6: Computers | C6: 706 | D6: 6707000
A7: Smartwatch | B7: Mobiles | C7: 754 | D7: 4901000
A8: Webcam | B8: Networking | C8: 794 | D8: 2382000
A9: Headphones | B9: Accessories | C9: 730 | D9: 1825000
A10: Router | B10: Networking | C10: 780 | D10: 1716000
A11: Power Bank | B11: Accessories | C11: 707 | D11: 1060500
A12: Keyboard | B12: Accessories | C12: 776 | D12: 931200
A13: Mouse | B13: Accessories | C13: 839 | D13: 503400

Sheet Sales Detail
A1: sale_date | B1: sale_year | C1: sale_month | D1: salesperson | E1: region | F1: product_name | G1: category | H1: quantity | I1: amount
A2: 46129 | B2: 2026 | C2: 4 | D2: Salesperson 08 | E2: West | F2: Mouse | G2: Accessories | H2: 1 | I2: 600
A3: 46305 | B3: 2026 | C3: 10 | D3: Salesperson 04 | E3: South | F3: Mouse | G3: Accessories | H3: 3 | I3: 1800
A4: 46066 | B4: 2026 | C4: 2 | D4: Salesperson 03 | E4: East | F4: Mouse | G4: Accessories | H4: 3 | I4: 1800
A5: 46282 | B5: 2026 | C5: 9 | D5: Salesperson 07 | E5: North | F5: Mouse | G5: Accessories | H5: 4 | I5: 2400
A6: 46148 | B6: 2026 | C6: 5 | D6: Salesperson 02 | E6: South | F6: Mouse | G6: Accessories | H6: 2 | I6: 1200
A7: 46156 | B7: 2026 | C7: 5 | D7: Salesperson 08 | E7: West | F7: Mouse | G7: Accessories | H7: 1 | I7: 600
A8: 46235 | B8: 2026 | C8: 8 | D8: Salesperson 02 | E8: South | F8: Mouse | G8: Accessories | H8: 3 | I8: 1800
A9: 46091 | B9: 2026 | C9: 3 | D9: Salesperson 06 | E9: North | F9: Mouse | G9: Accessories | H9: 4 | I9: 2400
A10: 46176 | B10: 2026 | C10: 6 | D10: Salesperson 04 | E10: South | F10: Mouse | G10: Accessories | H10: 2 | I10: 1200
A11: 46319 | B11: 2026 | C11: 10 | D11: Salesperson 08 | E11: West | F11: Mouse | G11: Accessories | H11: 5 | I11: 3000
A12: 46114 | B12: 2026 | C12: 4 | D12: Salesperson 05 | E12: West | F12: Mouse | G12: Accessories | H12: 1 | I12: 600
A13: 46159 | B13: 2026 | C13: 5 | D13: Salesperson 06 | E13: North | F13: Mouse | G13: Accessories | H13: 1 | I13: 600
... A3001: 46159 | B3001: 2026 | C3001: 5 | D3001: Salesperson 04 | E3001: South | F3001: Router | G3001: Networking | H3001: 3 | I3001: 6600

Sheet Target Detail
A1: salesperson | B1: region | C1: target_year | D1: target_month | E1: target_amount | F1: actual_amount | G1: achievement_pct | H1: status
A2: Salesperson 02 | B2: South | C2: 2026 | D2: 1 | E2: 1566000 | F2: 1691400 | G2: 108 | H2: Achieved
A3: Salesperson 01 | B3: East | C3: 2026 | D3: 7 | E3: 1525000 | F3: 1354000 | G3: 88.8 | H3: Near target
A4: Salesperson 07 | B4: North | C4: 2026 | D4: 5 | E4: 1379000 | F4: 1207500 | G4: 87.6 | H4: Near target
A5: Salesperson 02 | B5: South | C5: 2026 | D5: 3 | E5: 968000 | F5: 1091300 | G5: 112.7 | H5: Achieved
A6: Salesperson 05 | B6: West | C6: 2026 | D6: 4 | E6: 1049000 | F6: 1070500 | G6: 102 | H6: Achieved
A7: Salesperson 05 | B7: West | C7: 2026 | D7: 8 | E7: 1777000 | F7: 1790600 | G7: 100.8 | H7: Achieved
A8: Salesperson 03 | B8: East | C8: 2026 | D8: 1 | E8: 919000 | F8: 1124200 | G8: 122.3 | H8: Achieved
A9: Salesperson 06 | B9: North | C9: 2026 | D9: 8 | E9: 1532000 | F9: 1828400 | G9: 119.3 | H9: Achieved
A10: Salesperson 08 | B10: West | C10: 2026 | D10: 10 | E10: 1816000 | F10: 1625400 | G10: 89.5 | H10: Near target
A11: Salesperson 01 | B11: East | C11: 2026 | D11: 1 | E11: 1549000 | F11: 1851000 | G11: 119.5 | H11: Achieved
A12: Salesperson 06 | B12: North | C12: 2026 | D12: 7 | E12: 1155000 | F12: 1225400 | G12: 106.1 | H12: Achieved
A13: Salesperson 02 | B13: South | C13: 2026 | D13: 6 | E13: 1840000 | F13: 1590600 | G13: 86.4 | H13: Near target
... A81: Salesperson 05 | B81: West | C81: 2026 | D81: 9 | E81: 1473000 | F81: 1779600 | G81: 120.8 | H81: Achieved

Sheet Helper Tables
C1: HELPER TABLES: feed the charts. Do not edit.
C2: Year | D2: =Dashboard!$B$11 -> 2026
C3: Region filter | D3: =IF(Dashboard!$B$15="All","*",Dashboard!$B$15) -> *
C4: Month no (0=All) | D4: =IFERROR(MATCH(Dashboard!$B$19,$D$10:$D$21,0),0) -> 0
C5: Month from | D5: =IF($D$4=0,1,$D$4) -> 1
C6: Month to | D6: =IF($D$4=0,12,$D$4) -> 12
C7: Daily month | D7: =IF($D$4=0,SUMPRODUCT(MAX((v_sales_detail[sale_year]=$D$2)*v_sales_detail[sale_month])),$D$4) -> 10
C9: Month no | D9: Month | E9: Target | F9: Revenue | G9: Delta | H9: Delta + | I9: Delta - | J9: Revenue
C10: 1 | D10: Jan | E10: =SUMIFS(v_target_vs_actual[target_amount],v_target_vs_actual[target_year],$D$2,v_target_vs_actual[target_month],C10,v_target_vs_actual[region],$D$3) -> 10536000 | F10: =SUMIFS(v_sales_detail[amount],v_sales_detail[sale_year],$D$2,v_sales_detail[sale_month],C10,v_sales_detail[region],$D$3) -> 11000700 | G10: =F10-E10 -> 464700 | H10: =MAX(G10,0) -> 464700 | I10: =MIN(G10,0) -> 0 | J10: =IF(F10=0,NA(),F10) -> 11000700
C11: 2 | D11: Feb | E11: =SUMIFS(v_target_vs_actual[target_amount],v_target_vs_actual[target_year],$D$2,v_target_vs_actual[target_month],C11,v_target_vs_actual[region],$D$3) -> 9005000 | F11: =SUMIFS(v_sales_detail[amount],v_sales_detail[sale_year],$D$2,v_sales_detail[sale_month],C11,v_sales_detail[region],$D$3) -> 9660300 | G11: =F11-E11 -> 655300 | H11: =MAX(G11,0) -> 655300 | I11: =MIN(G11,0) -> 0 | J11: =IF(F11=0,NA(),F11) -> 9660300
C12: 3 | D12: Mar | E12: =SUMIFS(v_target_vs_actual[target_amount],v_target_vs_actual[target_year],$D$2,v_target_vs_actual[target_month],C12,v_target_vs_actual[region],$D$3) -> 8673000 | F12: =SUMIFS(v_sales_detail[amount],v_sales_detail[sale_year],$D$2,v_sales_detail[sale_month],C12,v_sales_detail[region],$D$3) -> 9313200 | G12: =F12-E12 -> 640200 | H12: =MAX(G12,0) -> 640200 | I12: =MIN(G12,0) -> 0 | J12: =IF(F12=0,NA(),F12) -> 9313200
C13: 4 | D13: Apr | E13: =SUMIFS(v_target_vs_actual[target_amount],v_target_vs_actual[target_year],$D$2,v_target_vs_actual[target_month],C13,v_target_vs_actual[region],$D$3) -> 8307000 | F13: =SUMIFS(v_sales_detail[amount],v_sales_detail[sale_year],$D$2,v_sales_detail[sale_month],C13,v_sales_detail[region],$D$3) -> 8479500 | G13: =F13-E13 -> 172500 | H13: =MAX(G13,0) -> 172500 | I13: =MIN(G13,0) -> 0 | J13: =IF(F13=0,NA(),F13) -> 8479500
C14: 5 | D14: May | E14: =SUMIFS(v_target_vs_actual[target_amount],v_target_vs_actual[target_year],$D$2,v_target_vs_actual[target_month],C14,v_target_vs_actual[region],$D$3) -> 9652000 | F14: =SUMIFS(v_sales_detail[amount],v_sales_detail[sale_year],$D$2,v_sales_detail[sale_month],C14,v_sales_detail[region],$D$3) -> 9746200 | G14: =F14-E14 -> 94200 | H14: =MAX(G14,0) -> 94200 | I14: =MIN(G14,0) -> 0 | J14: =IF(F14=0,NA(),F14) -> 9746200
C15: 6 | D15: Jun | E15: =SUMIFS(v_target_vs_actual[target_amount],v_target_vs_actual[target_year],$D$2,v_target_vs_actual[target_month],C15,v_target_vs_actual[region],$D$3) -> 10158000 | F15: =SUMIFS(v_sales_detail[amount],v_sales_detail[sale_year],$D$2,v_sales_detail[sale_month],C15,v_sales_detail[region],$D$3) -> 10017300 | G15: =F15-E15 -> -140700 | H15: =MAX(G15,0) -> 0 | I15: =MIN(G15,0) -> -140700 | J15: =IF(F15=0,NA(),F15) -> 10017300
C16: 7 | D16: Jul | E16: =SUMIFS(v_target_vs_actual[target_amount],v_target_vs_actual[target_year],$D$2,v_target_vs_actual[target_month],C16,v_target_vs_actual[region],$D$3) -> 8373000 | F16: =SUMIFS(v_sales_detail[amount],v_sales_detail[sale_year],$D$2,v_sales_detail[sale_month],C16,v_sales_detail[region],$D$3) -> 8746500 | G16: =F16-E16 -> 373500 | H16: =MAX(G16,0) -> 373500 | I16: =MIN(G16,0) -> 0 | J16: =IF(F16=0,NA(),F16) -> 8746500
C17: 8 | D17: Aug | E17: =SUMIFS(v_target_vs_actual[target_amount],v_target_vs_actual[target_year],$D$2,v_target_vs_actual[target_month],C17,v_target_vs_actual[region],$D$3) -> 11163000 | F17: =SUMIFS(v_sales_detail[amount],v_sales_detail[sale_year],$D$2,v_sales_detail[sale_month],C17,v_sales_detail[region],$D$3) -> 11131900 | G17: =F17-E17 -> -31100 | H17: =MAX(G17,0) -> 0 | I17: =MIN(G17,0) -> -31100 | J17: =IF(F17=0,NA(),F17) -> 11131900
C18: 9 | D18: Sep | E18: =SUMIFS(v_target_vs_actual[target_amount],v_target_vs_actual[target_year],$D$2,v_target_vs_actual[target_month],C18,v_target_vs_actual[region],$D$3) -> 11051000 | F18: =SUMIFS(v_sales_detail[amount],v_sales_detail[sale_year],$D$2,v_sales_detail[sale_month],C18,v_sales_detail[region],$D$3) -> 11360800 | G18: =F18-E18 -> 309800 | H18: =MAX(G18,0) -> 309800 | I18: =MIN(G18,0) -> 0 | J18: =IF(F18=0,NA(),F18) -> 11360800
C19: 10 | D19: Oct | E19: =SUMIFS(v_target_vs_actual[target_amount],v_target_vs_actual[target_year],$D$2,v_target_vs_actual[target_month],C19,v_target_vs_actual[region],$D$3) -> 10054000 | F19: =SUMIFS(v_sales_detail[amount],v_sales_detail[sale_year],$D$2,v_sales_detail[sale_month],C19,v_sales_detail[region],$D$3) -> 9535700 | G19: =F19-E19 -> -518300 | H19: =MAX(G19,0) -> 0 | I19: =MIN(G19,0) -> -518300 | J19: =IF(F19=0,NA(),F19) -> 9535700
C20: 11 | D20: Nov | E20: =SUMIFS(v_target_vs_actual[target_amount],v_target_vs_actual[target_year],$D$2,v_target_vs_actual[target_month],C20,v_target_vs_actual[region],$D$3) -> 0 | F20: =SUMIFS(v_sales_detail[amount],v_sales_detail[sale_year],$D$2,v_sales_detail[sale_month],C20,v_sales_detail[region],$D$3) -> 0 | G20: =F20-E20 -> 0 | H20: =MAX(G20,0) -> 0 | I20: =MIN(G20,0) -> 0 | J20: =IF(F20=0,NA(),F20) -> #N/A
C21: 12 | D21: Dec | E21: =SUMIFS(v_target_vs_actual[target_amount],v_target_vs_actual[target_year],$D$2,v_target_vs_actual[target_month],C21,v_target_vs_actual[region],$D$3) -> 0 | F21: =SUMIFS(v_sales_detail[amount],v_sales_detail[sale_year],$D$2,v_sales_detail[sale_month],C21,v_sales_detail[region],$D$3) -> 0 | G21: =F21-E21 -> 0 | H21: =MAX(G21,0) -> 0 | I21: =MIN(G21,0) -> 0 | J21: =IF(F21=0,NA(),F21) -> #N/A
C23: KPIs
C24: Revenue | D24: =SUMIFS(v_sales_detail[amount],v_sales_detail[sale_year],$D$2,v_sales_detail[region],$D$3,v_sales_detail[sale_month],">="&$D$5,v_sales_detail[sale_month],"<="&$D$6) -> 98992100
C25: Target | D25: =SUMIFS(v_target_vs_actual[target_amount],v_target_vs_actual[target_year],$D$2,v_target_vs_actual[region],$D$3,v_target_vs_actual[target_month],">="&$D$5,v_target_vs_actual[target_month],"<="&$D$6) -> 96972000
C26: Delta | D26: =D24-D25 -> 2020100
C27: Sales Records | D27: =COUNTIFS(v_sales_detail[sale_year],$D$2,v_sales_detail[region],$D$3,v_sales_detail[sale_month],">="&$D$5,v_sales_detail[sale_month],"<="&$D$6) -> 3000
C28: Achievement | D28: =IFERROR(D24/D25,0) -> 1.0208318
C29: Reached | D29: =MIN(D28,1) -> 1
C30: Remaining | D30: =1-D29 -> 0
C32: Region | D32: Revenue | E32: Target | F32: Achievement
C33: East | D33: =SUMIFS(v_sales_detail[amount],v_sales_detail[sale_year],$D$2,v_sales_detail[region],C33,v_sales_detail[sale_month],">="&$D$5,v_sales_detail[sale_month],"<="&$D$6) -> 22278800 | E33: =SUMIFS(v_target_vs_actual[target_amount],v_target_vs_actual[target_year],$D$2,v_target_vs_actual[region],C33,v_target_vs_actual[target_month],">="&$D$5,v_target_vs_actual[target_month],"<="&$D$6) -> 21919000 | F33: =IFERROR(D33/E33,0) -> 1.016415
C34: North | D34: =SUMIFS(v_sales_detail[amount],v_sales_detail[sale_year],$D$2,v_sales_detail[region],C34,v_sales_detail[sale_month],">="&$D$5,v_sales_detail[sale_month],"<="&$D$6) -> 23328800 | E34: =SUMIFS(v_target_vs_actual[target_amount],v_target_vs_actual[target_year],$D$2,v_target_vs_actual[region],C34,v_target_vs_actual[target_month],">="&$D$5,v_target_vs_actual[target_month],"<="&$D$6) -> 22182000 | F34: =IFERROR(D34/E34,0) -> 1.0516996
C35: South | D35: =SUMIFS(v_sales_detail[amount],v_sales_detail[sale_year],$D$2,v_sales_detail[region],C35,v_sales_detail[sale_month],">="&$D$5,v_sales_detail[sale_month],"<="&$D$6) -> 25222200 | E35: =SUMIFS(v_target_vs_actual[target_amount],v_target_vs_actual[target_year],$D$2,v_target_vs_actual[region],C35,v_target_vs_actual[target_month],">="&$D$5,v_target_vs_actual[target_month],"<="&$D$6) -> 24856000 | F35: =IFERROR(D35/E35,0) -> 1.0147329
C36: West | D36: =SUMIFS(v_sales_detail[amount],v_sales_detail[sale_year],$D$2,v_sales_detail[region],C36,v_sales_detail[sale_month],">="&$D$5,v_sales_detail[sale_month],"<="&$D$6) -> 28162300 | E36: =SUMIFS(v_target_vs_actual[target_amount],v_target_vs_actual[target_year],$D$2,v_target_vs_actual[region],C36,v_target_vs_actual[target_month],">="&$D$5,v_target_vs_actual[target_month],"<="&$D$6) -> 28015000 | F36: =IFERROR(D36/E36,0) -> 1.0052579
C39: Salesperson | D39: Region | E39: Target | F39: Revenue | G39: Achievement
C40: =IF(OR(Dashboard!$B$15="All",INDEX(tb1people[region],1)=Dashboard!$B$15),INDEX(tb1people[salesperson],1),"") -> Salesperson 02 | D40: =INDEX(tb1people[region],1) -> South | E40: =IF(OR(Dashboard!$B$15="All",D40=Dashboard!$B$15),SUMIFS(v_target_vs_actual[target_amount],v_target_vs_actual[salesperson],C40,v_target_vs_actual[target_year],$D$2,v_target_vs_actual[target_month],">="&$D$5,v_target_vs_actual[target_month],"<="&$D$6),NA()) -> 12927000 | F40: =IF(OR(Dashboard!$B$15="All",D40=Dashboard!$B$15),SUMIFS(v_sales_detail[amount],v_sales_detail[salesperson],C40,v_sales_detail[sale_year],$D$2,v_sales_detail[sale_month],">="&$D$5,v_sales_detail[sale_month],"<="&$D$6),NA()) -> 13075700 | G40: =IFERROR(F40/E40,NA()) -> 1.0115031
C41: =IF(OR(Dashboard!$B$15="All",INDEX(tb1people[region],2)=Dashboard!$B$15),INDEX(tb1people[salesperson],2),"") -> Salesperson 06 | D41: =INDEX(tb1people[region],2) -> North | E41: =IF(OR(Dashboard!$B$15="All",D41=Dashboard!$B$15),SUMIFS(v_target_vs_actual[target_amount],v_target_vs_actual[salesperson],C41,v_target_vs_actual[target_year],$D$2,v_target_vs_actual[target_month],">="&$D$5,v_target_vs_actual[target_month],"<="&$D$6),NA()) -> 10889000 | F41: =IF(OR(Dashboard!$B$15="All",D41=Dashboard!$B$15),SUMIFS(v_sales_detail[amount],v_sales_detail[salesperson],C41,v_sales_detail[sale_year],$D$2,v_sales_detail[sale_month],">="&$D$5,v_sales_detail[sale_month],"<="&$D$6),NA()) -> 11962100 | G41: =IFERROR(F41/E41,NA()) -> 1.098549
C42: =IF(OR(Dashboard!$B$15="All",INDEX(tb1people[region],3)=Dashboard!$B$15),INDEX(tb1people[salesperson],3),"") -> Salesperson 04 | D42: =INDEX(tb1people[region],3) -> South | E42: =IF(OR(Dashboard!$B$15="All",D42=Dashboard!$B$15),SUMIFS(v_target_vs_actual[target_amount],v_target_vs_actual[salesperson],C42,v_target_vs_actual[target_year],$D$2,v_target_vs_actual[target_month],">="&$D$5,v_target_vs_actual[target_month],"<="&$D$6),NA()) -> 11929000 | F42: =IF(OR(Dashboard!$B$15="All",D42=Dashboard!$B$15),SUMIFS(v_sales_detail[amount],v_sales_detail[salesperson],C42,v_sales_detail[sale_year],$D$2,v_sales_detail[sale_month],">="&$D$5,v_sales_detail[sale_month],"<="&$D$6),NA()) -> 12146500 | G42: =IFERROR(F42/E42,NA()) -> 1.0182329
C43: =IF(OR(Dashboard!$B$15="All",INDEX(tb1people[region],4)=Dashboard!$B$15),INDEX(tb1people[salesperson],4),"") -> Salesperson 05 | D43: =INDEX(tb1people[region],4) -> West | E43: =IF(OR(Dashboard!$B$15="All",D43=Dashboard!$B$15),SUMIFS(v_target_vs_actual[target_amount],v_target_vs_actual[salesperson],C43,v_target_vs_actual[target_year],$D$2,v_target_vs_actual[target_month],">="&$D$5,v_target_vs_actual[target_month],"<="&$D$6),NA()) -> 14080000 | F43: =IF(OR(Dashboard!$B$15="All",D43=Dashboard!$B$15),SUMIFS(v_sales_detail[amount],v_sales_detail[salesperson],C43,v_sales_detail[sale_year],$D$2,v_sales_detail[sale_month],">="&$D$5,v_sales_detail[sale_month],"<="&$D$6),NA()) -> 14145700 | G43: =IFERROR(F43/E43,NA()) -> 1.0046662
C44: =IF(OR(Dashboard!$B$15="All",INDEX(tb1people[region],5)=Dashboard!$B$15),INDEX(tb1people[salesperson],5),"") -> Salesperson 07 | D44: =INDEX(tb1people[region],5) -> North | E44: =IF(OR(Dashboard!$B$15="All",D44=Dashboard!$B$15),SUMIFS(v_target_vs_actual[target_amount],v_target_vs_actual[salesperson],C44,v_target_vs_actual[target_year],$D$2,v_target_vs_actual[target_month],">="&$D$5,v_target_vs_actual[target_month],"<="&$D$6),NA()) -> 11293000 | F44: =IF(OR(Dashboard!$B$15="All",D44=Dashboard!$B$15),SUMIFS(v_sales_detail[amount],v_sales_detail[salesperson],C44,v_sales_detail[sale_year],$D$2,v_sales_detail[sale_month],">="&$D$5,v_sales_detail[sale_month],"<="&$D$6),NA()) -> 11366700 | G44: =IFERROR(F44/E44,NA()) -> 1.0065262
C45: =IF(OR(Dashboard!$B$15="All",INDEX(tb1people[region],6)=Dashboard!$B$15),INDEX(tb1people[salesperson],6),"") -> Salesperson 03 | D45: =INDEX(tb1people[region],6) -> East | E45: =IF(OR(Dashboard!$B$15="All",D45=Dashboard!$B$15),SUMIFS(v_target_vs_actual[target_amount],v_target_vs_actual[salesperson],C45,v_target_vs_actual[target_year],$D$2,v_target_vs_actual[target_month],">="&$D$5,v_target_vs_actual[target_month],"<="&$D$6),NA()) -> 11819000 | F45: =IF(OR(Dashboard!$B$15="All",D45=Dashboard!$B$15),SUMIFS(v_sales_detail[amount],v_sales_detail[salesperson],C45,v_sales_detail[sale_year],$D$2,v_sales_detail[sale_month],">="&$D$5,v_sales_detail[sale_month],"<="&$D$6),NA()) -> 11831100 | G45: =IFERROR(F45/E45,NA()) -> 1.0010238
...
